

```python
# 异常处理的语法
try :
	检测范围
except Exception[as reason]:
	出现异常（Exception）后的处理代码
```



```python
# 实例
try:
    f = open('异常处理')
    print(f.read())
    f.close()
    input()
except OSError:
    print("文件出错了！")
# 执行后会出现：文件出错了！


# 又或者可以显示出错误的原因
try:
    f = open('异常处理')
    print(f.read())
    f.close()
    input()
except OSError as reason:
    print("文件出错了！" + str(reason))
# 执行后会出现：文件出错了！[Errno 2] No such file or directory: '异常处理'


# 同时，一个 try 后面可以接多个 except 
try:
    sum = 1 + '1'
    f = open('异常处理')
    print(f.read())
    f.close()
    input()
except OSError as reason:
    print("文件出错了！" + str(reason))
except TypeError as reason:
    print("类型出错了！" + str(reason))
# 执行后会出现：类型出错了！unsupported operand type(s) for +: 'int' and 'str'


# 当程序中的错误不是 except后包含的错误时，还是会出现一堆红色的报错
# 如果想要解决所有的显示，可以直接不添加错误类型，
		# 但这将无法根据情况判断错误产生的原因，
		# 而且有时还会捕捉用户的一些正常操作当成错误，比如终端程序的 Ctrl + c ，
		# 也会被提示错误，所以不推荐

try:
    int('ABC')
    sum = 1 + '1'
    f = open('异常处理')
    print(f.read())
    f.close()
    input()
except :
    print("程序出错了！")
# 执行后会出现：程序出错了！

# 有时为了方便书写，也会这样写
try:
    sum = 1 + '1'
    f = open('异常处理')
    print(f.read())
    f.close()
    input()
except (OSError, TypeError):
    print("出错了！")
# 执行后会出现：出错了！



# 还有一种情况，要添加无论是否有错误，都要执行的代码
try :
	检测范围
except Exception[as reason]:
	出现异常（Exception）后的处理代码
finally :
	无论如何都会被执行的代码


# 也可以自己主动引入异常，只要使用 raise 
>>> raise
Traceback (most recent call last):
  File "<pyshell#1>", line 1, in <module>
    raise
RuntimeError: No active exception to reraise

# 但多数使用raise时都会跟上要报出的异常
>>> raise OSError
Traceback (most recent call last):
  File "<pyshell#2>", line 1, in <module>
    raise OSError
OSError

# 还可以在报出的异常中添加提示信息
>>> raise OSError('操作不当，产生异常')
Traceback (most recent call last):
  File "<pyshell#3>", line 1, in <module>
    raise OSError('操作不当，产生异常')
OSError: 操作不当，产生异常
```

